{
 "cells": [
  {
   "cell_type": "code",
   "execution_count": 1,
   "id": "297a793f-099d-45f3-b64e-10fd70cace49",
   "metadata": {
    "tags": []
   },
   "outputs": [],
   "source": [
    "%reload_ext jupyter_ai_magics"
   ]
  },
  {
   "cell_type": "code",
   "execution_count": 2,
   "id": "01d054df-6fed-4c53-9fd1-27e5e09d64f9",
   "metadata": {
    "tags": []
   },
   "outputs": [
    {
     "data": {
      "text/plain": [
       "1.0"
      ]
     },
     "execution_count": 2,
     "metadata": {},
     "output_type": "execute_result"
    }
   ],
   "source": [
    "2/2"
   ]
  },
  {
   "cell_type": "code",
   "execution_count": 3,
   "id": "1d28e4d2-1677-4a3a-b489-94c95d7233ec",
   "metadata": {
    "tags": []
   },
   "outputs": [
    {
     "ename": "ZeroDivisionError",
     "evalue": "division by zero",
     "output_type": "error",
     "traceback": [
      "\u001b[0;31m---------------------------------------------------------------------------\u001b[0m",
      "\u001b[0;31mZeroDivisionError\u001b[0m                         Traceback (most recent call last)",
      "Cell \u001b[0;32mIn[3], line 1\u001b[0m\n\u001b[0;32m----> 1\u001b[0m \u001b[38;5;241;43m2\u001b[39;49m\u001b[38;5;241;43m/\u001b[39;49m\u001b[38;5;241;43m0\u001b[39;49m\n",
      "\u001b[0;31mZeroDivisionError\u001b[0m: division by zero"
     ]
    }
   ],
   "source": [
    "2/0"
   ]
  },
  {
   "cell_type": "code",
   "execution_count": 4,
   "id": "d184cff2-e70b-4b14-8dca-119cd36d6cff",
   "metadata": {
    "tags": []
   },
   "outputs": [
    {
     "name": "stdout",
     "output_type": "stream",
     "text": [
      "Exception type: ZeroDivisionError\n",
      "Exception value: division by zero\n",
      "Traceback: None\n"
     ]
    }
   ],
   "source": [
    "print(Err[3])"
   ]
  },
  {
   "cell_type": "code",
   "execution_count": 5,
   "id": "267decf3-9a23-4ca1-a2fa-b472c0e911c8",
   "metadata": {},
   "outputs": [
    {
     "data": {
      "text/markdown": [
       "The ZeroDivisionError occurs when a number is divided by zero. In this case, the code tried to divide by zero, which is not valid and caused the error. The traceback information is not available, which means there is no additional information about where the error occurred in the code."
      ],
      "text/plain": [
       "<IPython.core.display.Markdown object>"
      ]
     },
     "execution_count": 5,
     "metadata": {},
     "output_type": "execute_result"
    }
   ],
   "source": [
    "%%ai chatgpt\n",
    "Explain the following Python error:\n",
    "    {Err[3]}"
   ]
  },
  {
   "cell_type": "code",
   "execution_count": null,
   "id": "6c1420e5-adc7-433d-9bf7-be2dd84b2877",
   "metadata": {},
   "outputs": [],
   "source": []
  }
 ],
 "metadata": {
  "kernelspec": {
   "display_name": "Python 3 (ipykernel)",
   "language": "python",
   "name": "python3"
  },
  "language_info": {
   "codemirror_mode": {
    "name": "ipython",
    "version": 3
   },
   "file_extension": ".py",
   "mimetype": "text/x-python",
   "name": "python",
   "nbconvert_exporter": "python",
   "pygments_lexer": "ipython3",
   "version": "3.10.9"
  }
 },
 "nbformat": 4,
 "nbformat_minor": 5
}
